I'm sorry, but an uncaught exception occurred.

While running game code:
  File "game/script.rpy", line 16, in script
    init python:
  File "game/script.rpy", line 51, in <module>
    ToL_mark = Mark()
  File "game/script.rpy", line 22, in __init__
    _self.nakop = random.randint(0, 5)
NameError: name '_self' is not defined

-- Full Traceback ------------------------------------------------------------

Full traceback:
  File "game/script.rpy", line 16, in script
    init python:
  File "C:\Users\until\Downloads\renpy-8.1.3-sdk.7z\renpy-8.1.3-sdk\renpy\ast.py", line 1138, in execute
    renpy.python.py_exec_bytecode(self.code.bytecode, self.hide, store=self.store)
  File "C:\Users\until\Downloads\renpy-8.1.3-sdk.7z\renpy-8.1.3-sdk\renpy\python.py", line 1122, in py_exec_bytecode
    exec(bytecode, globals, locals)
  File "game/script.rpy", line 51, in <module>
    ToL_mark = Mark()
  File "game/script.rpy", line 22, in __init__
    _self.nakop = random.randint(0, 5)
NameError: name '_self' is not defined

Windows-10-10.0.19045 AMD64
Ren'Py 8.1.3.23091805
Game 1.0
Sat Dec 23 09:41:15 2023
